INFO 2021-06-04 16:25:13,834 remote_connection.py:117 __init__ Could not connect to port 4723 on host localhost
INFO 2021-06-04 16:25:13,834 remote_connection.py:136 __init__ Could not get IP address for host: localhost
DEBUG 2021-06-04 16:25:13,835 remote_connection.py:388 _request POST http://localhost:4723/wd/hub/session {"capabilities": {"firstMatch": [{"platformName": "Android", "appium:platformVersion": "10", "appium:deviceName": "89LJQWROR47TCYKJ", "appium:appPackage": "tv.danmaku.bili", "appium:appActivity": ".ui.splash.SplashActivity", "appium:unicodeKeyboard": false, "appium:resetKeyboard": false, "appium:noReset": true, "appium:newCommandTimeout": 6000, "appium:automationName": "UiAutomator2"}]}, "desiredCapabilities": {"platformName": "Android", "platformVersion": "10", "deviceName": "89LJQWROR47TCYKJ", "appPackage": "tv.danmaku.bili", "appActivity": ".ui.splash.SplashActivity", "unicodeKeyboard": false, "resetKeyboard": false, "noReset": true, "newCommandTimeout": 6000, "automationName": "UiAutomator2"}}
DEBUG 2021-06-04 16:25:13,836 connectionpool.py:231 _new_conn Starting new HTTP connection (1): localhost:4723
DEBUG 2021-06-04 16:25:17,888 retry.py:576 increment Incremented Retry for (url='/wd/hub/session'): Retry(total=2, connect=None, read=None, redirect=None, status=None)
WARNING 2021-06-04 16:25:17,889 connectionpool.py:781 urlopen Retrying (Retry(total=2, connect=None, read=None, redirect=None, status=None)) after connection broken by 'NewConnectionError('<urllib3.connection.HTTPConnection object at 0x000002B52D665E08>: Failed to establish a new connection: [WinError 10061] 由于目标计算机积极拒绝，无法连接。')': /wd/hub/session
DEBUG 2021-06-04 16:25:17,890 connectionpool.py:231 _new_conn Starting new HTTP connection (2): localhost:4723
DEBUG 2021-06-04 16:25:21,945 retry.py:576 increment Incremented Retry for (url='/wd/hub/session'): Retry(total=1, connect=None, read=None, redirect=None, status=None)
WARNING 2021-06-04 16:25:21,947 connectionpool.py:781 urlopen Retrying (Retry(total=1, connect=None, read=None, redirect=None, status=None)) after connection broken by 'NewConnectionError('<urllib3.connection.HTTPConnection object at 0x000002B52D6815C8>: Failed to establish a new connection: [WinError 10061] 由于目标计算机积极拒绝，无法连接。')': /wd/hub/session
DEBUG 2021-06-04 16:25:21,948 connectionpool.py:231 _new_conn Starting new HTTP connection (3): localhost:4723
DEBUG 2021-06-04 16:25:26,011 retry.py:576 increment Incremented Retry for (url='/wd/hub/session'): Retry(total=0, connect=None, read=None, redirect=None, status=None)
WARNING 2021-06-04 16:25:26,013 connectionpool.py:781 urlopen Retrying (Retry(total=0, connect=None, read=None, redirect=None, status=None)) after connection broken by 'NewConnectionError('<urllib3.connection.HTTPConnection object at 0x000002B52D688088>: Failed to establish a new connection: [WinError 10061] 由于目标计算机积极拒绝，无法连接。')': /wd/hub/session
DEBUG 2021-06-04 16:25:26,014 connectionpool.py:231 _new_conn Starting new HTTP connection (4): localhost:4723
