INFO 2021-06-08 17:37:18,267 remote_connection.py:117 __init__ Could not connect to port 4723 on host localhost
INFO 2021-06-08 17:37:18,267 remote_connection.py:136 __init__ Could not get IP address for host: localhost
DEBUG 2021-06-08 17:37:18,268 remote_connection.py:388 _request POST http://localhost:4723/wd/hub/session {"capabilities": {"firstMatch": [{"platformName": "Android", "appium:platformVersion": "11", "appium:deviceName": "89LJQWROR47TCYKJ", "appium:appPackage": "com.tencent.mm", "appium:appActivity": ".ui.LauncherUI", "appium:unicodeKeyboard": false, "appium:resetKeyboard": false, "appium:noReset": true, "appium:newCommandTimeout": 6000, "appium:automationName": "UiAutomator2"}]}, "desiredCapabilities": {"platformName": "Android", "platformVersion": "11", "deviceName": "89LJQWROR47TCYKJ", "appPackage": "com.tencent.mm", "appActivity": ".ui.LauncherUI", "unicodeKeyboard": false, "resetKeyboard": false, "noReset": true, "newCommandTimeout": 6000, "automationName": "UiAutomator2"}}
DEBUG 2021-06-08 17:37:18,269 connectionpool.py:231 _new_conn Starting new HTTP connection (1): localhost:4723
DEBUG 2021-06-08 17:37:22,327 retry.py:576 increment Incremented Retry for (url='/wd/hub/session'): Retry(total=2, connect=None, read=None, redirect=None, status=None)
WARNING 2021-06-08 17:37:22,327 connectionpool.py:781 urlopen Retrying (Retry(total=2, connect=None, read=None, redirect=None, status=None)) after connection broken by 'NewConnectionError('<urllib3.connection.HTTPConnection object at 0x000001FF8B992548>: Failed to establish a new connection: [WinError 10061] 由于目标计算机积极拒绝，无法连接。')': /wd/hub/session
DEBUG 2021-06-08 17:37:22,328 connectionpool.py:231 _new_conn Starting new HTTP connection (2): localhost:4723
DEBUG 2021-06-08 17:37:26,379 retry.py:576 increment Incremented Retry for (url='/wd/hub/session'): Retry(total=1, connect=None, read=None, redirect=None, status=None)
WARNING 2021-06-08 17:37:26,379 connectionpool.py:781 urlopen Retrying (Retry(total=1, connect=None, read=None, redirect=None, status=None)) after connection broken by 'NewConnectionError('<urllib3.connection.HTTPConnection object at 0x000001FF8B992D88>: Failed to establish a new connection: [WinError 10061] 由于目标计算机积极拒绝，无法连接。')': /wd/hub/session
DEBUG 2021-06-08 17:37:26,380 connectionpool.py:231 _new_conn Starting new HTTP connection (3): localhost:4723
DEBUG 2021-06-08 17:37:30,430 retry.py:576 increment Incremented Retry for (url='/wd/hub/session'): Retry(total=0, connect=None, read=None, redirect=None, status=None)
WARNING 2021-06-08 17:37:30,430 connectionpool.py:781 urlopen Retrying (Retry(total=0, connect=None, read=None, redirect=None, status=None)) after connection broken by 'NewConnectionError('<urllib3.connection.HTTPConnection object at 0x000001FF8B9AE708>: Failed to establish a new connection: [WinError 10061] 由于目标计算机积极拒绝，无法连接。')': /wd/hub/session
DEBUG 2021-06-08 17:37:30,431 connectionpool.py:231 _new_conn Starting new HTTP connection (4): localhost:4723
