INFO 2021-06-04 17:30:39,943 remote_connection.py:117 __init__ Could not connect to port 4723 on host localhost
INFO 2021-06-04 17:30:39,943 remote_connection.py:136 __init__ Could not get IP address for host: localhost
DEBUG 2021-06-04 17:30:39,944 remote_connection.py:388 _request POST http://localhost:4723/wd/hub/session {"capabilities": {"firstMatch": [{"platformName": "Android", "appium:platformVersion": "10", "appium:deviceName": "89LJQWROR47TCYKJ", "appium:appPackage": "com.tencent.mobileqq", "appium:appActivity": ".ui.splash.SplashActivity", "appium:unicodeKeyboard": false, "appium:resetKeyboard": false, "appium:noReset": true, "appium:newCommandTimeout": 6000, "appium:automationName": "UiAutomator2"}]}, "desiredCapabilities": {"platformName": "Android", "platformVersion": "10", "deviceName": "89LJQWROR47TCYKJ", "appPackage": "com.tencent.mobileqq", "appActivity": ".ui.splash.SplashActivity", "unicodeKeyboard": false, "resetKeyboard": false, "noReset": true, "newCommandTimeout": 6000, "automationName": "UiAutomator2"}}
DEBUG 2021-06-04 17:30:39,945 connectionpool.py:231 _new_conn Starting new HTTP connection (1): localhost:4723
DEBUG 2021-06-04 17:30:43,989 retry.py:576 increment Incremented Retry for (url='/wd/hub/session'): Retry(total=2, connect=None, read=None, redirect=None, status=None)
WARNING 2021-06-04 17:30:43,991 connectionpool.py:781 urlopen Retrying (Retry(total=2, connect=None, read=None, redirect=None, status=None)) after connection broken by 'NewConnectionError('<urllib3.connection.HTTPConnection object at 0x00000207F392B2C8>: Failed to establish a new connection: [WinError 10061] 由于目标计算机积极拒绝，无法连接。')': /wd/hub/session
DEBUG 2021-06-04 17:30:43,992 connectionpool.py:231 _new_conn Starting new HTTP connection (2): localhost:4723
DEBUG 2021-06-04 17:30:48,044 retry.py:576 increment Incremented Retry for (url='/wd/hub/session'): Retry(total=1, connect=None, read=None, redirect=None, status=None)
WARNING 2021-06-04 17:30:48,044 connectionpool.py:781 urlopen Retrying (Retry(total=1, connect=None, read=None, redirect=None, status=None)) after connection broken by 'NewConnectionError('<urllib3.connection.HTTPConnection object at 0x00000207F392BB08>: Failed to establish a new connection: [WinError 10061] 由于目标计算机积极拒绝，无法连接。')': /wd/hub/session
DEBUG 2021-06-04 17:30:48,045 connectionpool.py:231 _new_conn Starting new HTTP connection (3): localhost:4723
