INFO 2021-06-07 10:03:37,840 remote_connection.py:117 __init__ Could not connect to port 4723 on host localhost
INFO 2021-06-07 10:03:37,841 remote_connection.py:136 __init__ Could not get IP address for host: localhost
DEBUG 2021-06-07 10:03:37,842 remote_connection.py:388 _request POST http://localhost:4723/wd/hub/session {"capabilities": {"firstMatch": [{"platformName": "Android", "appium:platformVersion": "10", "appium:deviceName": "doesn't", "appium:appPackage": "com.ss.android.ugc.aweme", "appium:appActivity": ".splash.SplashActivity", "appium:unicodeKeyboard": false, "appium:resetKeyboard": false, "appium:noReset": true, "appium:newCommandTimeout": 6000, "appium:automationName": "UiAutomator2"}]}, "desiredCapabilities": {"platformName": "Android", "platformVersion": "10", "deviceName": "doesn't", "appPackage": "com.ss.android.ugc.aweme", "appActivity": ".splash.SplashActivity", "unicodeKeyboard": false, "resetKeyboard": false, "noReset": true, "newCommandTimeout": 6000, "automationName": "UiAutomator2"}}
DEBUG 2021-06-07 10:03:37,844 connectionpool.py:231 _new_conn Starting new HTTP connection (1): localhost:4723
DEBUG 2021-06-07 10:03:41,890 retry.py:576 increment Incremented Retry for (url='/wd/hub/session'): Retry(total=2, connect=None, read=None, redirect=None, status=None)
WARNING 2021-06-07 10:03:41,891 connectionpool.py:781 urlopen Retrying (Retry(total=2, connect=None, read=None, redirect=None, status=None)) after connection broken by 'NewConnectionError('<urllib3.connection.HTTPConnection object at 0x0000011D30636C48>: Failed to establish a new connection: [WinError 10061] 由于目标计算机积极拒绝，无法连接。')': /wd/hub/session
DEBUG 2021-06-07 10:03:41,891 connectionpool.py:231 _new_conn Starting new HTTP connection (2): localhost:4723
DEBUG 2021-06-07 10:03:45,962 retry.py:576 increment Incremented Retry for (url='/wd/hub/session'): Retry(total=1, connect=None, read=None, redirect=None, status=None)
WARNING 2021-06-07 10:03:45,962 connectionpool.py:781 urlopen Retrying (Retry(total=1, connect=None, read=None, redirect=None, status=None)) after connection broken by 'NewConnectionError('<urllib3.connection.HTTPConnection object at 0x0000011D30629908>: Failed to establish a new connection: [WinError 10061] 由于目标计算机积极拒绝，无法连接。')': /wd/hub/session
DEBUG 2021-06-07 10:03:45,962 connectionpool.py:231 _new_conn Starting new HTTP connection (3): localhost:4723
